<?xml version="1.0"?>
<robot xmlns:xacro="http://ros.org/wiki/xacro">

  <xacro:include filename="$(find nextagea_description)/urdf/general/common.xacro" />
  <xacro:include filename="$(find nextagea_description)/urdf/general/materials.xacro" />

  <xacro:macro name="nextagea_robot" params="namespace:=/nextagea/ nextagea_gazebo_ros_control:=true">

    <!-- NOTE: The poses of headmount and hand cameras are NOT precisely adjusted to
    the 3D model nor the actual hardware config. These configs
    are meant for a rapid prototyping only. -->

    <xacro:camera_joint_link_gzplugin
        camera_name="CAMERA_HEAD_L" link_parent="HEAD_JOINT1_Link"
        jnt_displacement_x="${jnt_head_camera_displacement_x}" jnt_displacement_y="${jnt_head_camera_displacement_y}" jnt_displacement_z="${jnt_head_camera_displacement_z}"
        jnt_rotation_x="0" jnt_rotation_y="${jnt_head_camera_rot_y}" jnt_rotation_z="0"
        link_displacement_x="0.0325" link_displacement_y="0" link_displacement_z="0"
        link_rotation_x="0" link_rotation_y="${M_PI/2}" link_rotation_z="-${link_head_camera_rot_z}" />

    <xacro:camera_joint_link_gzplugin
        camera_name="CAMERA_HEAD_R" link_parent="HEAD_JOINT1_Link"
        jnt_displacement_x="${jnt_head_camera_displacement_x}" jnt_displacement_y="-${jnt_head_camera_displacement_y}" jnt_displacement_z="${jnt_head_camera_displacement_z}"
        jnt_rotation_x="0" jnt_rotation_y="${jnt_head_camera_rot_y}" jnt_rotation_z="0"
        link_displacement_x="0.0325" link_displacement_y="0" link_displacement_z="0"
        link_rotation_x="0" link_rotation_y="${M_PI/2}" link_rotation_z="${link_head_camera_rot_z}" />

    <xacro:gazebo_nx_link name="WAIST" color="Black" />
    <link name="WAIST">
      <visual>
        <origin xyz="0 0 0" rpy="0 0 0"/>
        <geometry>
          <mesh filename="package://nextagea_description/urdf/meshes/WAIST_Link_mesh.dae"/>
        </geometry>
      </visual>
      <collision>
        <origin xyz="0.0 0 0.098" rpy="0 0 0"/>
        <geometry>
          <cylinder length="0.376" radius="0.06"/>
        </geometry>
      </collision>
      <inertial>
        <mass value="5" />
        <origin xyz="0 0 0.15" rpy="0 0 0"/>
        <xacro:nxa_box_inertia_def x="0.2" y="0.2" z="0.3" mass="5"/>
      </inertial>
    </link>

    <xacro:gazebo_nx_link name="CHEST_JOINT0_Link" color="Black" />
    <link name="CHEST_JOINT0_Link">
      <visual>
        <origin xyz="0 0 0" rpy="0 0 0"/>
        <geometry>
          <mesh filename="package://nextagea_description/urdf/meshes/CHEST_JOINT0_Link_mesh.dae"/>
        </geometry>
      </visual>
      <collision>
        <origin xyz="0 0 0.1575" rpy="0 0 0"/>
        <geometry>
          <cylinder length="0.385" radius="0.08"/>
        </geometry>
      </collision>
      <collision>
        <origin xyz="0.04 0.135 0.0423" rpy="0 0 0"/>
        <geometry>
          <cylinder length="0.09" radius="0.05"/>
        </geometry>
      </collision>
      <collision>
        <origin xyz="0.04 -0.135 0.0423" rpy="0 0 0"/>
        <geometry>
          <cylinder length="0.09" radius="0.05"/>
        </geometry>
      </collision>
      <collision>
        <origin xyz="0 0 0.055" rpy="0 0 0"/>
        <geometry>
          <box size="0.23 0.18 0.12"/>
        </geometry>
      </collision>
      <collision>
        <origin xyz="-0.04 0 0.2325" rpy="0 0 0"/>
        <geometry>
          <box size="0.25 0.18 0.245"/>
        </geometry>
      </collision>
      <collision>
        <origin xyz="-0.1525 0 0.279" rpy="0 0 0"/>
        <geometry>
          <box size="0.17 0.29 0.225"/>
        </geometry>
      </collision>
      <collision>
        <origin xyz="0.03 0 0.315" rpy="0 0 0"/>
        <geometry>
          <box size="0.085 0.5 0.0365"/>
        </geometry>
      </collision>
      <inertial>
        <mass value="10.0" />
        <origin xyz="0 0 0.2" rpy="0 -0 0"/>
        <xacro:nxa_box_inertia_def x="0.25" y="0.25" z="0.3" mass="10"/>
      </inertial>
    </link>

    <xacro:gazebo_nx_link name="HEAD_JOINT0_Link" color="Black" />
    <link name="HEAD_JOINT0_Link">
      <visual>
        <origin xyz="0 0 0" rpy="0 0 0"/>
        <geometry>
          <mesh filename="package://nextagea_description/urdf/meshes/HEAD_JOINT0_Link_mesh.dae"/>
        </geometry>
      </visual>
      <collision>
        <origin xyz="0 0.01 0.08" rpy="1.57079 0 0"/>
        <geometry>
          <cylinder length="0.135" radius="0.035"/>
        </geometry>
      </collision>
      <inertial>
        <mass value="0.317929" />
        <origin xyz="0 0.00547848 0" rpy="0 -0 0"/>
        <xacro:nxa_box_inertia_def x="0.1" y="0.1" z="0.1" mass="0.317929"/>
      </inertial>
    </link>

    <xacro:gazebo_nx_link name="HEAD_JOINT1_Link" color="Black" />
    <link name="HEAD_JOINT1_Link">
      <visual>
        <origin xyz="0 0 0" rpy="0 0 0"/>
        <geometry>
          <mesh filename="package://nextagea_description/urdf/meshes/HEAD_JOINT1_Link_mesh.dae"/>
        </geometry>
      </visual>
      <collision>
        <origin xyz="-0.05 0 0.12" rpy="0 0.26 0"/>
        <geometry>
          <box size="0.27 0.22 0.115"/>
        </geometry>
      </collision>
      <inertial>
        <mass value="0.4" />
        <origin xyz="-0.05 0 0.12" rpy="0 0.26 0"/>
        <xacro:nxa_box_inertia_def x="0.27" y="0.22" z="0.115" mass="0.4"/>
      </inertial>
    </link>

    <xacro:gazebo_nx_link name="LARM_JOINT0_Link" color="Black" />
    <link name="LARM_JOINT0_Link">
      <visual>
        <origin xyz="0 0 0" rpy="0 0 0"/>
        <geometry>
          <mesh filename="package://nextagea_description/urdf/meshes/LARM_JOINT0_Link_mesh.dae"/>
        </geometry>
      </visual>
      <collision>
        <origin xyz="0 0.00775 0.095" rpy="0 0 0"/>
        <geometry>
          <box size="0.1 0.0815 0.19"/>
        </geometry>
      </collision>
      <collision>
        <origin xyz="0 0.0875 0.066" rpy="1.57079 0 0"/>
        <geometry>
          <cylinder length="0.175" radius="0.042"/>
        </geometry>
      </collision>
      <collision>
        <origin xyz="0 0.125 0.145" rpy="-0.7 0 0"/>
        <geometry>
          <box size="0.048 0.1 0.035"/>
        </geometry>
      </collision>
      <inertial>
        <mass value="1.32626" />
        <origin xyz="0.0 0.05 0.05" rpy="0 -0 0"/>
        <inertia ixx="0.00207537" ixy="0.00011276" ixz="8.927e-05" iyy="0.00240295" iyz="-4.57e-05" izz="0.00141912"/>
      </inertial>
    </link>

    <xacro:gazebo_nx_link name="LARM_JOINT1_Link" color="Black" />
    <link name="LARM_JOINT1_Link">
      <visual>
        <origin xyz="0 0 0" rpy="0 0 0"/>
        <geometry>
          <mesh filename="package://nextagea_description/urdf/meshes/LARM_JOINT1_Link_mesh.dae"/>
        </geometry>
      </visual>
      <collision>
        <origin xyz="-0.043 0.12 -0.13" rpy="0 0.3 0"/>
        <geometry>
          <box size="0.08 0.11 0.28"/>
        </geometry>
      </collision>
      <collision>
        <origin xyz="-0.03 0.0518 -0.236" rpy="0 0.45 0"/>
        <geometry>
          <box size="0.122 0.0338 0.062"/>
        </geometry>
      </collision>
      <inertial>
        <mass value="1.14898" />
        <origin xyz="-0.04 0.1 -0.12" rpy="0 -0 0"/>
        <inertia ixx="0.0154168" ixy="9.95417e-07" ixz="3.38147e-06" iyy="0.0147117" iyz="0.00213719" izz="0.0012658"/>
      </inertial>
    </link>

    <xacro:gazebo_nx_link name="LARM_JOINT2_Link" color="Black" />
    <link name="LARM_JOINT2_Link">
      <visual>
        <origin xyz="0 0 0" rpy="0 0 0"/>
        <geometry>
          <mesh filename="package://nextagea_description/urdf/meshes/LARM_JOINT2_Link_mesh.dae"/>
        </geometry>
      </visual>
      <collision>
        <origin xyz="0 0.025 0" rpy="1.57079 0 0"/>
        <geometry>
          <cylinder length="0.11" radius="0.049"/>
        </geometry>
      </collision>
      <collision>
        <origin xyz="0.0945 0.015 -0.03" rpy="0 0 0"/>
        <geometry>
          <box size="0.119 0.125 0.1"/>
        </geometry>
      </collision>
      <collision>
        <origin xyz="0.17 0 -0.03" rpy="0 1.57079 0"/>
        <geometry>
          <cylinder length="0.04" radius="0.047"/>
        </geometry>
      </collision>
      <inertial>
        <mass value="0.577518" />
        <origin xyz="0.1 0.01167107 -0.04" rpy="0 -0 0"/>
        <inertia ixx="0.00143966" ixy="-3e-07" ixz="1.2e-06" iyy="0.00141763" iyz="-7.596e-05" izz="0.0001972"/>
      </inertial>
    </link>

    <xacro:gazebo_nx_link name="LARM_JOINT3_Link" color="Black" />
    <link name="LARM_JOINT3_Link">
      <visual>
        <origin xyz="0 0 0" rpy="0 0 0"/>
        <geometry>
          <mesh filename="package://nextagea_description/urdf/meshes/LARM_JOINT3_Link_mesh.dae"/>
        </geometry>
      </visual>
      <collision>
        <origin xyz="0.1495 -0.003 0" rpy="1.57079 0 0"/>
        <geometry>
          <cylinder length="0.12" radius="0.035"/>
        </geometry>
      </collision>
      <collision>
        <origin xyz="0.075 0.0 0.018" rpy="0 1.57079 0"/>
        <geometry>
          <cylinder length="0.15" radius="0.04"/>
        </geometry>
      </collision>
      <collision>
        <origin xyz="0.0585 0.01 0.0185" rpy="0 0 0"/>
        <geometry>
          <box size="0.093 0.112 0.037"/>
        </geometry>
      </collision>
      <inertial>
        <mass value="0.457418" />
        <origin xyz="0.1 -0.00395812 -0.00273" rpy="0 -0 0"/>
        <inertia ixx="0.00069205" ixy="3e-08" ixz="5.2e-07" iyy="0.00068903" iyz="-1.915e-05" izz="0.00013509"/>
      </inertial>
    </link>

    <xacro:gazebo_nx_link name="LARM_JOINT4_Link" color="Black" />
    <link name="LARM_JOINT4_Link">
      <visual>
        <origin xyz="0 0 0" rpy="0 0 0"/>
        <geometry>
          <mesh filename="package://nextagea_description/urdf/meshes/LARM_JOINT4_Link_mesh.dae"/>
        </geometry>
      </visual>
      <collision>
        <origin xyz="0 -0.002 -0.06" rpy="0 0 0"/>
        <geometry>
          <box size="0.04 0.118 0.06"/>
        </geometry>
      </collision>
      <collision>
        <origin xyz="0 0 -0.08" rpy="0 0 0"/>
        <geometry>
          <cylinder length="0.08" radius="0.037"/>
        </geometry>
      </collision>
      <inertial>
        <mass value="0.418434" />
        <origin xyz="0.00243131 0.00379733 -0.0577036" rpy="0 -0 0"/>
        <inertia ixx="0.00052016" ixy="1.69e-06" ixz="7.9e-06" iyy="0.00050569" iyz="-5.377e-05" izz="0.00014004"/>
      </inertial>
    </link>

    <xacro:gazebo_nx_link name="LARM_JOINT5_Link" color="Black" />
    <link name="LARM_JOINT5_Link">
      <visual>
        <origin xyz="0 0 0" rpy="0 0 0"/>
        <geometry>
          <mesh filename="package://nextagea_description/urdf/meshes/LARM_JOINT5_Link_mesh.dae"/>
        </geometry>
      </visual>
      <collision>
        <origin xyz="0 0 0.0065" rpy="0 0 0"/>
        <geometry>
          <cylinder length="0.013" radius="0.037"/>
        </geometry>
      </collision>
      <inertial>
        <mass value="1.05156" />
        <origin xyz="0.0 0.0 -0.08" rpy="0 -0 0"/>
        <inertia ixx="0.00194072" ixy="1.1e-07" ixz="-0.00042482" iyy="0.00209392" iyz="1.2e-07" izz="0.00035788"/>
      </inertial>
    </link>

    <xacro:gazebo_nx_link name="RARM_JOINT0_Link" color="Black" />
    <link name="RARM_JOINT0_Link">
      <visual>
        <origin xyz="0 0 0" rpy="0 0 0"/>
        <geometry>
          <mesh filename="package://nextagea_description/urdf/meshes/RARM_JOINT0_Link_mesh.dae"/>
        </geometry>
      </visual>
      <collision>
        <origin xyz="0 -0.00775 0.095" rpy="0 0 0"/>
        <geometry>
          <box size="0.1 0.0815 0.19"/>
        </geometry>
      </collision>
      <collision>
        <origin xyz="0 -0.0875 0.066" rpy="1.57079 0 0"/>
        <geometry>
          <cylinder length="0.175" radius="0.042"/>
        </geometry>
      </collision>
      <collision>
        <origin xyz="0 -0.125 0.145" rpy="0.7 0 0"/>
        <geometry>
          <box size="0.048 0.1 0.035"/>
        </geometry>
      </collision>
      <inertial>
        <mass value="1.32626" />
        <origin xyz="0.0 -0.05 0.05" rpy="0 -0 0"/>
        <inertia ixx="0.00207537" ixy="-0.00011276" ixz="8.927e-05" iyy="0.00240295" iyz="4.57e-05" izz="0.00141912"/>
      </inertial>
    </link>

    <xacro:gazebo_nx_link name="RARM_JOINT1_Link" color="Black" />
    <link name="RARM_JOINT1_Link">
      <visual>
        <origin xyz="0 0 0" rpy="0 0 0"/>
        <geometry>
          <mesh filename="package://nextagea_description/urdf/meshes/RARM_JOINT1_Link_mesh.dae"/>
        </geometry>
      </visual>
      <collision>
        <origin xyz="-0.043 -0.12 -0.13" rpy="0 0.3 0"/>
        <geometry>
          <box size="0.08 0.11 0.28"/>
        </geometry>
      </collision>
      <collision>
        <origin xyz="-0.03 -0.0518 -0.236" rpy="0 0.45 0"/>
        <geometry>
          <box size="0.122 0.0338 0.062"/>
        </geometry>
      </collision>
      <inertial>
        <mass value="1.14898" />
        <origin xyz="-0.04 -0.1 -0.12" rpy="0 -0 0"/>
        <inertia ixx="0.0154168" ixy="-9.95417e-07" ixz="3.38147e-06" iyy="0.0147117" iyz="-0.00213719" izz="0.0012658"/>
      </inertial>
    </link>

    <xacro:gazebo_nx_link name="RARM_JOINT2_Link" color="Black" />
    <link name="RARM_JOINT2_Link">
      <visual>
        <origin xyz="0 0 0" rpy="0 0 0"/>
        <geometry>
          <mesh filename="package://nextagea_description/urdf/meshes/RARM_JOINT2_Link_mesh.dae"/>
        </geometry>
      </visual>
      <collision>
        <origin xyz="0 -0.025 0" rpy="1.57079 0 0"/>
        <geometry>
          <cylinder length="0.11" radius="0.049"/>
        </geometry>
      </collision>
      <collision>
        <origin xyz="0.0945 -0.015 -0.03" rpy="0 0 0"/>
        <geometry>
          <box size="0.119 0.125 0.1"/>
        </geometry>
      </collision>
      <collision>
        <origin xyz="0.17 0 -0.03" rpy="0 1.57079 0"/>
        <geometry>
          <cylinder length="0.04" radius="0.047"/>
        </geometry>
      </collision>
      <inertial>
        <mass value="0.577518" />
        <origin xyz="0.1 -0.01167107 -0.04" rpy="0 -0 0"/>
        <inertia ixx="0.00143966" ixy="3e-07" ixz="1.2e-06" iyy="0.00141763" iyz="7.596e-05" izz="0.0001972"/>
      </inertial>
    </link>

    <xacro:gazebo_nx_link name="RARM_JOINT3_Link" color="Black" />
    <link name="RARM_JOINT3_Link">
      <visual>
        <origin xyz="0 0 0" rpy="0 0 0"/>
        <geometry>
          <mesh filename="package://nextagea_description/urdf/meshes/RARM_JOINT3_Link_mesh.dae"/>
        </geometry>
      </visual>
      <collision>
        <origin xyz="0.1495 -0.003 0" rpy="1.57079 0 0"/>
        <geometry>
          <cylinder length="0.12" radius="0.035"/>
        </geometry>
      </collision>
      <collision>
        <origin xyz="0.075 0.0 0.018" rpy="0 1.57079 0"/>
        <geometry>
          <cylinder length="0.15" radius="0.04"/>
        </geometry>
      </collision>
      <collision>
        <origin xyz="0.0585 -0.01 0.0185" rpy="0 0 0"/>
        <geometry>
          <box size="0.093 0.112 0.037"/>
        </geometry>
      </collision>
      <inertial>
        <mass value="0.457418" />
        <origin xyz="0.1 0.00395812 -0.00273" rpy="0 -0 0"/>
        <inertia ixx="0.00069205" ixy="-3e-08" ixz="5.2e-07" iyy="0.00068903" iyz="1.915e-05" izz="0.00013509"/>
      </inertial>
    </link>

    <xacro:gazebo_nx_link name="RARM_JOINT4_Link" color="Black" />
    <link name="RARM_JOINT4_Link">
      <visual>
        <origin xyz="0 0 0" rpy="0 0 0"/>
        <geometry>
          <mesh filename="package://nextagea_description/urdf/meshes/RARM_JOINT4_Link_mesh.dae"/>
        </geometry>
      </visual>
      <collision>
        <origin xyz="0 -0.002 -0.06" rpy="0 0 0"/>
        <geometry>
          <box size="0.04 0.118 0.06"/>
        </geometry>
      </collision>
      <collision>
        <origin xyz="0 0 -0.08" rpy="0 0 0"/>
        <geometry>
          <cylinder length="0.08" radius="0.037"/>
        </geometry>
      </collision>
      <inertial>
        <mass value="0.418434" />
        <origin xyz="0.00243131 -0.00379733 -0.0577036" rpy="0 -0 0"/>
        <inertia ixx="0.00052016" ixy="-1.69e-06" ixz="7.9e-06" iyy="0.00050569" iyz="5.377e-05" izz="0.00014004"/>
      </inertial>
    </link>

    <xacro:gazebo_nx_link name="RARM_JOINT5_Link" color="Black" />
    <link name="RARM_JOINT5_Link">
      <visual>
        <origin xyz="0 0 0" rpy="0 0 0"/>
        <geometry>
          <mesh filename="package://nextagea_description/urdf/meshes/RARM_JOINT5_Link_mesh.dae"/>
        </geometry>
      </visual>
      <collision>
        <origin xyz="0 0 0.0065" rpy="0 0 0"/>
        <geometry>
          <cylinder length="0.013" radius="0.037"/>
        </geometry>
      </collision>
      <inertial>
        <mass value="1.05156" />
        <origin xyz="0.0 0.0 -0.08" rpy="0 -0 0"/>
        <inertia ixx="0.00194072" ixy="-1.1e-07" ixz="-0.00042482" iyy="0.00209392" iyz="-1.2e-07" izz="0.00035788"/>
      </inertial>
    </link>

    <xacro:transmission_nx_joint name="CHEST_JOINT0" />
    <joint name="CHEST_JOINT0" type="revolute">
      <parent link="WAIST"/>
      <child link="CHEST_JOINT0_Link"/>
      <origin xyz="0 0 0.267" rpy="0 0 0"/>
      <axis xyz="0 0 1"/>
      <limit lower="-3.14159" upper="3.14159" effort="100" velocity="2.513274"/>
      <dynamics damping="0.2" friction="0"/>
    </joint>

    <xacro:transmission_nx_joint name="HEAD_JOINT0" />
    <joint name="HEAD_JOINT0" type="revolute">
      <parent link="CHEST_JOINT0_Link"/>
      <child link="HEAD_JOINT0_Link"/>
      <origin xyz="0 0 0.302" rpy="0 0 0"/>
      <axis xyz="0 0 1"/>
      <limit lower="-1.22173" upper="1.22173" effort="100" velocity="6.684611"/>
    </joint>


    <xacro:transmission_nx_joint name="HEAD_JOINT1" />
    <joint name="HEAD_JOINT1" type="revolute">
      <parent link="HEAD_JOINT0_Link"/>
      <child link="HEAD_JOINT1_Link"/>
      <origin xyz="0 0 0.08" rpy="0 0 0"/>
      <axis xyz="0 1 0"/>
      <limit lower="-0.401425" upper="1.308997" effort="100" velocity="6.684611"/>
    </joint>


    <xacro:transmission_nx_joint name="LARM_JOINT0" />
    <joint name="LARM_JOINT0" type="revolute">
      <parent link="CHEST_JOINT0_Link"/>
      <child link="LARM_JOINT0_Link"/>
      <origin xyz="0.04 0.135 0.1015" rpy="0 0 0"/>
      <axis xyz="0 0 1"/>
      <limit lower="-1.5707963" upper="1.5707963" effort="150" velocity="3.892084"/>
      <dynamics damping="0.5" friction="0.5"/>
    </joint>

    <xacro:transmission_nx_joint name="LARM_JOINT1" />
    <joint name="LARM_JOINT1" type="revolute">
      <parent link="LARM_JOINT0_Link"/>
      <child link="LARM_JOINT1_Link"/>
      <origin xyz="0 0 0.066" rpy="0 0 0"/>
      <axis xyz="0 1 0"/>
      <limit lower="-2.44346" upper="1.0471975" effort="150" velocity="2.426008"/>
      <dynamics damping="0.5" friction="0.5"/>
    </joint>


    <xacro:transmission_nx_joint name="LARM_JOINT2" />
    <joint name="LARM_JOINT2" type="revolute">
      <parent link="LARM_JOINT1_Link"/>
      <child link="LARM_JOINT2_Link"/>
      <origin xyz="0 0.095 -0.25" rpy="0 0 0"/>
      <axis xyz="0 1 0"/>
      <limit lower="-1.22173" upper="1.5707963" effort="150" velocity="3.630285"/>
      <dynamics damping="0.5" friction="0.5"/>
    </joint>


    <xacro:transmission_nx_joint name="LARM_JOINT3" />
    <joint name="LARM_JOINT3" type="revolute">
      <parent link="LARM_JOINT2_Link"/>
      <child link="LARM_JOINT3_Link"/>
      <origin xyz="0.1805 0 -0.03" rpy="0 0 0"/>
      <axis xyz="1 0 0"/>
      <limit lower="-3.1415926" upper="1.7453292" effort="150" velocity="6.352998"/>
      <dynamics damping="0.5" friction="0.5"/>
    </joint>

    <xacro:transmission_nx_joint name="LARM_JOINT4" />
    <joint name="LARM_JOINT4" type="revolute">
      <parent link="LARM_JOINT3_Link"/>
      <child link="LARM_JOINT4_Link"/>
      <origin xyz="0.1495 0 0" rpy="0 0 0"/>
      <axis xyz="0 1 0"/>
      <limit lower="-3.4" upper="1.134464" effort="150" velocity="6.352998"/>
      <dynamics damping="0.5" friction="0.5"/>
    </joint>


    <xacro:transmission_nx_joint name="LARM_JOINT5" />
    <joint name="LARM_JOINT5" type="revolute">
      <parent link="LARM_JOINT4_Link"/>
      <child link="LARM_JOINT5_Link"/>
      <origin xyz="0 0 -0.1335" rpy="0 0 0"/>
      <axis xyz="0 0 1"/>
      <limit lower="-2.7123889" upper="2.7123889" effort="150" velocity="6.352998"/>
      <dynamics damping="0.5" friction="0.5"/>
    </joint>

    <xacro:transmission_nx_joint name="RARM_JOINT0" />
    <joint name="RARM_JOINT0" type="revolute">
      <parent link="CHEST_JOINT0_Link"/>
      <child link="RARM_JOINT0_Link"/>
      <origin xyz="0.04 -0.135 0.1015" rpy="0 0 0"/>
      <axis xyz="0 0 1"/>
      <limit lower="-1.570796" upper="1.570796" effort="150" velocity="3.892084"/>
      <dynamics damping="0.5" friction="0.5"/>
    </joint>


    <xacro:transmission_nx_joint name="RARM_JOINT1" />
    <joint name="RARM_JOINT1" type="revolute">
      <parent link="RARM_JOINT0_Link"/>
      <child link="RARM_JOINT1_Link"/>
      <origin xyz="0 0 0.066" rpy="0 0 0"/>
      <axis xyz="0 1 0"/>
      <limit lower="-2.44346" upper="1.047197" effort="150" velocity="2.426008"/>
      <dynamics damping="0.5" friction="0.5"/>
    </joint>


    <xacro:transmission_nx_joint name="RARM_JOINT2" />
    <joint name="RARM_JOINT2" type="revolute">
      <parent link="RARM_JOINT1_Link"/>
      <child link="RARM_JOINT2_Link"/>
      <origin xyz="0 -0.095 -0.25" rpy="0 0 0"/>
      <axis xyz="0 1 0"/>
      <limit lower="-1.22173" upper="1.570796" effort="150" velocity="3.630285"/>
      <dynamics damping="0.5" friction="0.5"/>
    </joint>


    <xacro:transmission_nx_joint name="RARM_JOINT3" />
    <joint name="RARM_JOINT3" type="revolute">
      <parent link="RARM_JOINT2_Link"/>
      <child link="RARM_JOINT3_Link"/>
      <origin xyz="0.1805 0 -0.03" rpy="0 0 0"/>
      <axis xyz="1 0 0"/>
      <limit lower="-1.74532" upper="3.141592" effort="150" velocity="6.352998"/>
      <dynamics damping="0.5" friction="0.5"/>
    </joint>


    <xacro:transmission_nx_joint name="RARM_JOINT4" />
    <joint name="RARM_JOINT4" type="revolute">
      <parent link="RARM_JOINT3_Link"/>
      <child link="RARM_JOINT4_Link"/>
      <origin xyz="0.1495 0 0" rpy="0 0 0"/>
      <axis xyz="0 1 0"/>
      <limit lower="-3.4" upper="1.134464" effort="150" velocity="6.352998"/>
      <dynamics damping="0.5" friction="0.5"/>
    </joint>


    <xacro:transmission_nx_joint name="RARM_JOINT5" />
    <joint name="RARM_JOINT5" type="revolute">
      <parent link="RARM_JOINT4_Link"/>
      <child link="RARM_JOINT5_Link"/>
      <origin xyz="0 0 -0.1335" rpy="0 0 0"/>
      <axis xyz="0 0 1"/>
      <limit lower="-2.712388" upper="2.712388" effort="150" velocity="6.352998"/>
      <dynamics damping="0.5" friction="0.5"/>
    </joint>


    <!-- Gazebo plugin for ROS Control -->
    <xacro:if value="${nextagea_gazebo_ros_control}">
      <gazebo>
        <plugin name="gazebo_ros_control" filename="libgazebo_ros_control.so">
          <robotNamespace>${namespace}</robotNamespace>
          <eStopTopic>nextagea_hw/soft_estop</eStopTopic>
        </plugin>
      </gazebo>
    </xacro:if>

    <!-- Gazebo-Specific Link Properties -->
    <gazebo reference="CHEST_JOINT0">
      <implicitSpringDamper>1</implicitSpringDamper>
    </gazebo>
    <gazebo reference="HEAD_JOINT0">
      <implicitSpringDamper>1</implicitSpringDamper>
    </gazebo>
    <gazebo reference="HEAD_JOINT1">
      <implicitSpringDamper>1</implicitSpringDamper>
    </gazebo>
    <gazebo reference="LARM_JOINT0">
      <implicitSpringDamper>1</implicitSpringDamper>
    </gazebo>
    <gazebo reference="LARM_JOINT1">
      <implicitSpringDamper>1</implicitSpringDamper>
    </gazebo>
    <gazebo reference="LARM_JOINT2">
      <implicitSpringDamper>1</implicitSpringDamper>
    </gazebo>
    <gazebo reference="LARM_JOINT3">
      <implicitSpringDamper>1</implicitSpringDamper>
    </gazebo>
    <gazebo reference="LARM_JOINT4">
      <implicitSpringDamper>1</implicitSpringDamper>
    </gazebo>
    <gazebo reference="LARM_JOINT5">
      <implicitSpringDamper>1</implicitSpringDamper>
    </gazebo>
    <gazebo reference="RARM_JOINT0">
      <implicitSpringDamper>1</implicitSpringDamper>
    </gazebo>
    <gazebo reference="RARM_JOINT1">
      <implicitSpringDamper>1</implicitSpringDamper>
    </gazebo>
    <gazebo reference="RARM_JOINT2">
      <implicitSpringDamper>1</implicitSpringDamper>
    </gazebo>
    <gazebo reference="RARM_JOINT3">
      <implicitSpringDamper>1</implicitSpringDamper>
    </gazebo>
    <gazebo reference="RARM_JOINT4">
      <implicitSpringDamper>1</implicitSpringDamper>
    </gazebo>
    <gazebo reference="RARM_JOINT5">
      <implicitSpringDamper>1</implicitSpringDamper>
    </gazebo>

  </xacro:macro>

</robot>
